stderr of test 'ID.994842` in directory 'monetdb5/tests/BugsViaSourgeforce` itself:


# 00:30:00 >  
# 00:30:00 >  Mtimeout -timeout 180 Mserver "--config=/var/tmp/_PREFIX__GNU_32_d__/etc/monet.conf" --debug=10 --set "monet_mod_path=/var/tmp/_PREFIX__GNU_32_d__/lib/MonetDB" --set "gdk_dbfarm=/var/tmp/_PREFIX__GNU_32_d__/var/MonetDB/dbfarm" --set "sql_logdir=/var/tmp/_PREFIX__GNU_32_d__/var/MonetDB/log" --set mapi_port=48978 --set sql_port=56965 --set monet_prompt= --trace "--dbname=mTests_tests_BugsViaSourgeforce" "/var/tmp/_PREFIX__GNU_32_d__/lib/MonetDB/mapi.mil" ; echo ; echo Over..
# 00:30:00 >  


# 00:30:01 >  
# 00:30:01 >  Mtimeout -timeout 60 MapiClient -u monetdb -P monetdb "--config=/var/tmp/_PREFIX__GNU_32_d__/etc/monet.conf" --host=draco --port=48978 < ID.994842.milC
# 00:30:01 >  

MAPI  = monetdb@draco:46292
ACTION= mapi_next_result
QUERY = shutdown();
ERROR = Connection lost

# 00:30:01 >  
# 00:30:01 >  Mtimeout -timeout 60 Mshutdown.py "--config=/var/tmp/_PREFIX__GNU_32_d__/etc/monet.conf" --host=draco --port=48978
# 00:30:01 >  


# 00:30:02 >  
# 00:30:02 >  Done.
# 00:30:02 >  




