stderr of test 'grantAndRevokeUserLogedIN` in directory 'sql/test/Users` itself:


# 10:42:58 >  
# 10:42:58 >  "mserver5" "--debug=10" "--set" "gdk_nr_threads=0" "--set" "mapi_open=true" "--set" "mapi_port=33978" "--set" "mapi_usock=/var/tmp/mtest-2062/.s.monetdb.33978" "--set" "monet_prompt=" "--forcemito" "--set" "mal_listing=2" "--dbpath=/home/vera/Desktop/MonetDB/installation/var/MonetDB/mTests_sql_test_Users" "--set" "mal_listing=0" "--set" "embedded_r=yes"
# 10:42:58 >  

# builtin opt 	gdk_dbpath = /home/vera/Desktop/MonetDB/installation/var/monetdb5/dbfarm/demo
# builtin opt 	gdk_debug = 0
# builtin opt 	gdk_vmtrim = no
# builtin opt 	monet_prompt = >
# builtin opt 	monet_daemon = no
# builtin opt 	mapi_port = 50000
# builtin opt 	mapi_open = false
# builtin opt 	mapi_autosense = false
# builtin opt 	sql_optimizer = default_pipe
# builtin opt 	sql_debug = 0
# cmdline opt 	gdk_nr_threads = 0
# cmdline opt 	mapi_open = true
# cmdline opt 	mapi_port = 33978
# cmdline opt 	mapi_usock = /var/tmp/mtest-2062/.s.monetdb.33978
# cmdline opt 	monet_prompt = 
# cmdline opt 	mal_listing = 2
# cmdline opt 	gdk_dbpath = /home/vera/Desktop/MonetDB/installation/var/MonetDB/mTests_sql_test_Users
# cmdline opt 	mal_listing = 0
# cmdline opt 	embedded_r = yes
# cmdline opt 	gdk_debug = 536870922

# 10:42:59 >  
# 10:42:59 >  "/usr/bin/python2" "grantAndRevokeUserLogedIN.SQL.py" "grantAndRevokeUserLogedIN"
# 10:42:59 >  

Traceback (most recent call last):
  File "grantAndRevokeUserLogedIN.SQL.py", line 39, in <module>
    run(c2, 'UPDATE test SET x = -66 WHERE y = 66')
  File "grantAndRevokeUserLogedIN.SQL.py", line 26, in run
    r = conn.execute(sql)
  File "/home/vera/Desktop/MonetDB/installation/lib/python2.7/site-packages/monetdb/sql/connections.py", line 127, in execute
    return self.command('s' + query + '\n;')
  File "/home/vera/Desktop/MonetDB/installation/lib/python2.7/site-packages/monetdb/sql/connections.py", line 132, in command
    return self.mapi.cmd(command)
  File "/home/vera/Desktop/MonetDB/installation/lib/python2.7/site-packages/monetdb/mapi.py", line 178, in cmd
    raise OperationalError(response[1:])
monetdb.exceptions.OperationalError: UPDATE: insufficient privileges for user 'new_user' to update table 'test' on column 'x'


# 10:42:59 >  
# 10:42:59 >  "Done."
# 10:42:59 >  

